<!-- Copyright 2021 DeepMind Technologies Limited

     Licensed under the Apache License, Version 2.0 (the "License");
     you may not use this file except in compliance with the License.
     You may obtain a copy of the License at

         http://www.apache.org/licenses/LICENSE-2.0

     Unless required by applicable law or agreed to in writing, software
     distributed under the License is distributed on an "AS IS" BASIS,
     WITHOUT WARRANTIES OR CONDITIONS OF ANY KIND, either express or implied.
     See the License for the specific language governing permissions and
     limitations under the License.
-->

<mujoco model="2-link arm">
  <option collision="all" integrator = "RK4" >
   <flag energy="enable"/>
  </option>
  <visual>
    <rgba haze=".3 .3 .3 1"/>
  </visual>

  <default>
    <joint type="hinge" pos="0 0 0" axis="1 0 0" damping="0" stiffness="0"/>
  </default>

  <asset>
    <texture type="skybox" builtin="gradient" rgb1="0.6 0.6 0.6" rgb2="0 0 0" width="512" height="512"/>
    <texture name="texplane" type="2d" builtin="checker" rgb1=".25 .25 .25" rgb2=".3 .3 .3" width="512" height="512" mark="cross" markrgb=".8 .8 .8"/>
    <material name="matplane" reflectance="0.3" texture="texplane" texrepeat="1 1" texuniform="true"/>
  </asset>

  <worldbody>
    <geom name="floor" pos="0 0 -3.5" size="0 0 1" type="plane" material="matplane"/>
    
    <light directional="true" diffuse=".8 .8 .8" specular=".2 .2 .2" pos="5 0 0" dir="-1 0 0"/>
    <light directional="true" diffuse=".8 .8 .8" specular=".2 .2 .2" pos="0 0 5" dir="0 0 -1"/>

    <body name="link1" pos="0 0 0">
      <joint name="joint1"/>
      <geom name="l1geo" type="capsule" size="0.05" fromto="0 0 0  0 0 1" rgba=".1 .2 .1 1"/>      
      
      <body name="link2" pos="0 0 1">
        <joint name="joint2"/>
        <geom name="l2geo" type="capsule" size="0.05" fromto="0 0 0  0 0 1" rgba=".5 .1 .1 1"/>
      </body>
    </body>

  </worldbody>

 <sensor>
  <subtreecom name="COM" body="world"/>
  <subtreelinvel name="comvel" body="world"/>
  <subtreeangmom name="AngMom" body="world"/>
 </sensor>

  <contact>
    <exclude body1="world" body2="link1"/>
    <exclude body1="link1" body2="link2"/>
    <exclude body1="world" body2="link2"/>
  </contact>

  <actuator>
    <motor name="motor2" joint="joint2"/>
  </actuator>

</mujoco>
